Workbook

Sheet Denmark_turbine
A1: Turbine identifier (GSRN) | B1: Date of original connection to grid | C1: Capacity (kW) | D1: Rotor diameter (m) | E1: Hub height (m) | F1: Manufacture | G1: Model | H1: Local authority no | I1: Local authority name | J1: Type of location | K1: Cadastral district | L1: Cadastral no. | M1: X (east) coordinate UTM 32 Euref89 | N1: Y (north) coordinate UTM 32 Euref89 | O1: Origin of coordinates | P1: Distribution company installation number | Q1: Turbine | R1: turb_match
A2: 570715000002077638 | B2: 44539 | C2: 14000 | D2: 122 | E2: 160 | F2: SIEMENS | G2: Ukendt-Simens | H2: 787 | I2: Thisted | J2: LAND | K2: Østerild By, Østerild | L2: 4u | M2: 462928.99 | N2: 6323167.2 | O2: Stamdata | Q2: SIEMENS Ukendt-Simens | R2: =_xlfn.IFERROR(INDEX('model_byCAP'!$D$2:$D$377,MATCH(Q2,'model_byCAP'!$A$2:$A$377,0)),0) -> Siemens.SWT.3.0.101
A3: 570715000001661395 | B3: 43888 | C3: 10000 | D3: 193 | E3: 140 | F3: Siemens Wind Power A/S | G3: SG DD-193 / SG 10.0-193DD | H3: 787 | I3: Thisted | J3: LAND | K3: Østerild by, Østerild | L3: 4m | M3: 492926.99 | N3: 6322569.2 | O3: Stamdata | P3: 3507002 | Q3: Siemens Wind Power A/S SG DD-193 / SG 10.0-193DD | R3: =_xlfn.IFERROR(INDEX('model_byCAP'!$D$2:$D$377,MATCH(Q3,'model_byCAP'!$A$2:$A$377,0)),0) -> Siemens.Gamesa.SG.10.0.193
A4: 570715000001663276 | B4: 43858 | C4: 9500 | D4: 174 | E4: 130 | F4: MHI Vestas Offshore Wind A/S | G4: V164-8.0MW/8.3MW | H4: 787 | I4: Thisted | J4: LAND | K4: Hjardemål klit, Hjardemål | L4: 34 | M4: 492926 | N4: 6325569 | O4: Stamdata | P4: 3489007 | Q4: MHI Vestas Offshore Wind A/S V164-8.0MW/8.3MW | R4: =_xlfn.IFERROR(INDEX('model_byCAP'!$D$2:$D$377,MATCH(Q4,'model_byCAP'!$A$2:$A$377,0)),0) -> MHI.Vestas.V164.8400
A5: 570715000001616975 | B5: 43378 | C5: 8600 | D5: 167 | E5: 120.5 | F5: Ukendt | G5: Ukendt | H5: 787 | I5: Thisted | J5: LAND | K5: Østerild by, Østerild | L5: 4m | M5: 492960 | N5: 6323735 | O5: Stamdata | P5: 3492006 | Q5: Ukendt Ukendt | R5: =_xlfn.IFERROR(INDEX('model_byCAP'!$D$2:$D$377,MATCH(Q5,'model_byCAP'!$A$2:$A$377,0)),0) -> 0
A6: 570715000001542588 | B6: 44251 | C6: 8400 | D6: 167 | E6: 104 | F6: Siemens Wind Power A/S | G6: SG 8.0-167 DD | H6: 390 | I6: Vordingborg | J6: HAV | K6: Kriegers Flak | L6: Hav | M6: 744149 | N6: 6108859 | O6: Stamdata | P6: KFA 01R | Q6: Siemens Wind Power A/S SG 8.0-167 DD | R6: =_xlfn.IFERROR(INDEX('model_byCAP'!$D$2:$D$377,MATCH(Q6,'model_byCAP'!$A$2:$A$377,0)),0) -> Siemens.Gamesa.SG.8.0.167
A7: 570715000001542595 | B7: 44251 | C7: 8400 | D7: 167 | E7: 104 | F7: Siemens Wind Power A/S | G7: SG 8.0-167 DD | H7: 390 | I7: Vordingborg | J7: HAV | K7: Kriegers Flak | L7: Hav | M7: 741899 | N7: 6107869 | O7: Stamdata | P7: KFA 02Q | Q7: Siemens Wind Power A/S SG 8.0-167 DD | R7: =_xlfn.IFERROR(INDEX('model_byCAP'!$D$2:$D$377,MATCH(Q7,'model_byCAP'!$A$2:$A$377,0)),0) -> Siemens.Gamesa.SG.8.0.167
A8: 570715000001542601 | B8: 44250 | C8: 8400 | D8: 167 | E8: 104 | F8: Siemens Wind Power A/S | G8: SG 8.0-167 DD | H8: 390 | I8: Vordingborg | J8: HAV | K8: Kriegers Flak | L8: Hav | M8: 743789 | N8: 6107689 | O8: Stamdata | P8: KFA 03R | Q8: Siemens Wind Power A/S SG 8.0-167 DD | R8: =_xlfn.IFERROR(INDEX('model_byCAP'!$D$2:$D$377,MATCH(Q8,'model_byCAP'!$A$2:$A$377,0)),0) -> Siemens.Gamesa.SG.8.0.167
A9: 570715000001542618 | B9: 44255 | C9: 8400 | D9: 167 | E9: 104 | F9: Siemens Wind Power A/S | G9: SG 8.0-167 DD | H9: 390 | I9: Vordingborg | J9: HAV | K9: Kriegers Flak | L9: Hav | M9: 740639 | N9: 6107234 | O9: Stamdata | P9: KFA 04Q | Q9: Siemens Wind Power A/S SG 8.0-167 DD | R9: =_xlfn.IFERROR(INDEX('model_byCAP'!$D$2:$D$377,MATCH(Q9,'model_byCAP'!$A$2:$A$377,0)),0) -> Siemens.Gamesa.SG.8.0.167
A10: 570715000001542625 | B10: 44250 | C10: 8400 | D10: 167 | E10: 104 | F10: Siemens Wind Power A/S | G10: SG 8.0-167 DD | H10: 390 | I10: Vordingborg | J10: HAV | K10: Kriegers Flak | L10: Hav | M10: 743609 | N10: 6106429 | O10: Stamdata | P10: KFA 05R | Q10: Siemens Wind Power A/S SG 8.0-167 DD | R10: =_xlfn.IFERROR(INDEX('model_byCAP'!$D$2:$D$377,MATCH(Q10,'model_byCAP'!$A$2:$A$377,0)),0) -> Siemens.Gamesa.SG.8.0.167
A11: 570715000001542632 | B11: 44249 | C11: 8400 | D11: 167 | E11: 104 | F11: Siemens Wind Power A/S | G11: SG 8.0-167 DD | H11: 390 | I11: Vordingborg | J11: HAV | K11: Kriegers Flak | L11: Hav | M11: 740549 | N11: 6105979 | O11: Stamdata | P11: KFA 06Q | Q11: Siemens Wind Power A/S SG 8.0-167 DD | R11: =_xlfn.IFERROR(INDEX('model_byCAP'!$D$2:$D$377,MATCH(Q11,'model_byCAP'!$A$2:$A$377,0)),0) -> Siemens.Gamesa.SG.8.0.167
A12: 570715000001542649 | B12: 44240 | C12: 8400 | D12: 167 | E12: 104 | F12: Siemens Wind Power A/S | G12: SG 8.0-167 DD | H12: 390 | I12: Vordingborg | J12: HAV | K12: Kriegers Flak | L12: Hav | M12: 743789 | N12: 6105169 | O12: Stamdata | P12: KFA 07R | Q12: Siemens Wind Power A/S SG 8.0-167 DD | R12: =_xlfn.IFERROR(INDEX('model_byCAP'!$D$2:$D$377,MATCH(Q12,'model_byCAP'!$A$2:$A$377,0)),0) -> Siemens.Gamesa.SG.8.0.167
A13: 570715000001542656 | B13: 44252 | C13: 8400 | D13: 167 | E13: 104 | F13: Siemens Wind Power A/S | G13: SG 8.0-167 DD | H13: 390 | I13: Vordingborg | J13: HAV | K13: Kriegers Flak | L13: Hav | M13: 740369 | N13: 6104899 | O13: Stamdata | P13: KFA 08Q | Q13: Siemens Wind Power A/S SG 8.0-167 DD | R13: =_xlfn.IFERROR(INDEX('model_byCAP'!$D$2:$D$377,MATCH(Q13,'model_byCAP'!$A$2:$A$377,0)),0) -> Siemens.Gamesa.SG.8.0.167
A14: 570715000001542663 | B14: 44254 | C14: 8400 | D14: 167 | E14: 104 | F14: Siemens Wind Power A/S | G14: SG 8.0-167 DD | H14: 390 | I14: Vordingborg | J14: HAV | K14: Kriegers Flak | L14: Hav | M14: 740459 | N14: 6103819 | O14: Stamdata | P14: KFA 09P | Q14: Siemens Wind Power A/S SG 8.0-167 DD | R14: =_xlfn.IFERROR(INDEX('model_byCAP'!$D$2:$D$377,MATCH(Q14,'model_byCAP'!$A$2:$A$377,0)),0) -> Siemens.Gamesa.SG.8.0.167
A15: 570715000001542670 | B15: 44228 | C15: 8400 | D15: 167 | E15: 104 | F15: Siemens Wind Power A/S | G15: SG 8.0-167 DD | H15: 390 | I15: Vordingborg | J15: HAV | K15: Kriegers Flak | L15: Hav | M15: 744149 | N15: 6103639 | O15: Stamdata | P15: KFA 10O | Q15: Siemens Wind Power A/S SG 8.0-167 DD | R15: =_xlfn.IFERROR(INDEX('model_byCAP'!$D$2:$D$377,MATCH(Q15,'model_byCAP'!$A$2:$A$377,0)),0) -> Siemens.Gamesa.SG.8.0.167
A16: 570715000001542687 | B16: 44256 | C16: 8400 | D16: 167 | E16: 104 | F16: Siemens Wind Power A/S | G16: SG 8.0-167 DD | H16: 390 | I16: Vordingborg | J16: HAV | K16: Kriegers Flak | L16: Hav | M16: 740459 | N16: 6102739 | O16: Stamdata | P16: KFA 11P | Q16: Siemens Wind Power A/S SG 8.0-167 DD | R16: =_xlfn.IFERROR(INDEX('model_byCAP'!$D$2:$D$377,MATCH(Q16,'model_byCAP'!$A$2:$A$377,0)),0) -> Siemens.Gamesa.SG.8.0.167
A17: 570715000001542694 | B17: 44239 | C17: 8400 | D17: 167 | E17: 104 | F17: Siemens Wind Power A/S | G17: SG 8.0-167 DD | H17: 390 | I17: Vordingborg | J17: HAV | K17: Kriegers Flak | L17: Hav | M17: 744419 | N17: 6102559 | O17: Stamdata | P17: KFA 12O | Q17: Siemens Wind Power A/S SG 8.0-167 DD | R17: =_xlfn.IFERROR(INDEX('model_byCAP'!$D$2:$D$377,MATCH(Q17,'model_byCAP'!$A$2:$A$377,0)),0) -> Siemens.Gamesa.SG.8.0.167
... A77: 570715000001543295 | B77: 44352 | C77: 8400 | D77: 167 | E77: 104 | F77: Siemens Wind Power A/S | G77: SG 8.0-167 DD | H77: 390 | I77: Vordingborg | J77: HAV | K77: Kriegers Flak | L77: Hav | M77: 755669 | N77: 6100489 | O77: Stamdata | P77: KFB 69K | Q77: Siemens Wind Power A/S SG 8.0-167 DD | R77: =_xlfn.IFERROR(INDEX('model_byCAP'!$D$2:$D$377,MATCH(Q77,'model_byCAP'!$A$2:$A$377,0)),0) -> Siemens.Gamesa.SG.8.0.167
A78: 571313134499569550 | B78: 44115 | C78: 8400 | D78: 164 | E78: 118 | F78: MHI Vestas Offshore Wind A/S | G78: V164-8.0MW/8.3MW | H78: 561 | I78: Esbjerg | J78: LAND | K78: Måde Esbjerg Jorder | L78: 2i | M78: 468049.88 | N78: 6145616.5 | O78: Stamdata | Q78: MHI Vestas Offshore Wind A/S V164-8.0MW/8.3MW | R78: =_xlfn.IFERROR(INDEX('model_byCAP'!$D$2:$D$377,MATCH(Q78,'model_byCAP'!$A$2:$A$377,0)),0) -> MHI.Vestas.V164.8400
A79: 571313134499569574 | B79: 44114 | C79: 8400 | D79: 164 | E79: 118 | F79: MHI Vestas Offshore Wind A/S | G79: V164-8.0MW/8.3MW | H79: 561 | I79: Esbjerg | J79: LAND | K79: Måde Esbjerg Jorder | L79: 4æ | M79: 468533.63 | N79: 6145431 | O79: Stamdata | Q79: MHI Vestas Offshore Wind A/S V164-8.0MW/8.3MW | R79: =_xlfn.IFERROR(INDEX('model_byCAP'!$D$2:$D$377,MATCH(Q79,'model_byCAP'!$A$2:$A$377,0)),0) -> MHI.Vestas.V164.8400
A80: 570715000001613509 | B80: 43457 | C80: 8300 | D80: 164 | E80: 105 | F80: MHI Vestas Offshore Wind A/S | G80: V164-8.0MW/8.3MW | H80: 561 | I80: Esbjerg | J80: HAV | K80: Horns Rev | L80: Hav | M80: 408997 | N80: 6177653 | O80: Stamdata | P80: WH3 A01 | Q80: MHI Vestas Offshore Wind A/S V164-8.0MW/8.3MW | R80: =_xlfn.IFERROR(INDEX('model_byCAP'!$D$2:$D$377,MATCH(Q80,'model_byCAP'!$A$2:$A$377,0)),0) -> MHI.Vestas.V164.8400
A81: 570715000001613516 | B81: 43457 | C81: 8300 | D81: 164 | E81: 105 | F81: MHI Vestas Offshore Wind A/S | G81: V164-8.0MW/8.3MW | H81: 561 | I81: Esbjerg | J81: HAV | K81: Horns Rev | L81: Hav | M81: 409143 | N81: 6176505 | O81: Stamdata | P81: WH3 A02 | Q81: MHI Vestas Offshore Wind A/S V164-8.0MW/8.3MW | R81: =_xlfn.IFERROR(INDEX('model_byCAP'!$D$2:$D$377,MATCH(Q81,'model_byCAP'!$A$2:$A$377,0)),0) -> MHI.Vestas.V164.8400
A82: 570715000001613523 | B82: 43457 | C82: 8300 | D82: 164 | E82: 105 | F82: MHI Vestas Offshore Wind A/S | G82: V164-8.0MW/8.3MW | H82: 561 | I82: Esbjerg | J82: HAV | K82: Horns Rev | L82: Hav | M82: 409638 | N82: 6175486 | O82: Stamdata | P82: WH3 A03 | Q82: MHI Vestas Offshore Wind A/S V164-8.0MW/8.3MW | R82: =_xlfn.IFERROR(INDEX('model_byCAP'!$D$2:$D$377,MATCH(Q82,'model_byCAP'!$A$2:$A$377,0)),0) -> MHI.Vestas.V164.8400
A83: 570715000001613530 | B83: 43457 | C83: 8300 | D83: 164 | E83: 105 | F83: MHI Vestas Offshore Wind A/S | G83: V164-8.0MW/8.3MW | H83: 561 | I83: Esbjerg | J83: HAV | K83: Horns Rev | L83: Hav | M83: 410064 | N83: 6174402 | O83: Stamdata | P83: WH3 A04 | Q83: MHI Vestas Offshore Wind A/S V164-8.0MW/8.3MW | R83: =_xlfn.IFERROR(INDEX('model_byCAP'!$D$2:$D$377,MATCH(Q83,'model_byCAP'!$A$2:$A$377,0)),0) -> MHI.Vestas.V164.8400
A84: 570715000001613547 | B84: 43457 | C84: 8300 | D84: 164 | E84: 105 | F84: MHI Vestas Offshore Wind A/S | G84: V164-8.0MW/8.3MW | H84: 561 | I84: Esbjerg | J84: HAV | K84: Horns Rev | L84: Hav | M84: 410241 | N84: 6173317 | O84: Stamdata | P84: WH3 A05 | Q84: MHI Vestas Offshore Wind A/S V164-8.0MW/8.3MW | R84: =_xlfn.IFERROR(INDEX('model_byCAP'!$D$2:$D$377,MATCH(Q84,'model_byCAP'!$A$2:$A$377,0)),0) -> MHI.Vestas.V164.8400
A85: 570715000001613554 | B85: 43457 | C85: 8300 | D85: 164 | E85: 105 | F85: MHI Vestas Offshore Wind A/S | G85: V164-8.0MW/8.3MW | H85: 561 | I85: Esbjerg | J85: HAV | K85: Horns Rev | L85: Hav | M85: 410328 | N85: 6172214 | O85: Stamdata | P85: WH3 A06 | Q85: MHI Vestas Offshore Wind A/S V164-8.0MW/8.3MW | R85: =_xlfn.IFERROR(INDEX('model_byCAP'!$D$2:$D$377,MATCH(Q85,'model_byCAP'!$A$2:$A$377,0)),0) -> MHI.Vestas.V164.8400
A86: 570715000001613561 | B86: 43457 | C86: 8300 | D86: 164 | E86: 105 | F86: MHI Vestas Offshore Wind A/S | G86: V164-8.0MW/8.3MW | H86: 561 | I86: Esbjerg | J86: HAV | K86: Horns Rev | L86: Hav | M86: 410568 | N86: 6177763 | O86: Stamdata | P86: WH3 B01 | Q86: MHI Vestas Offshore Wind A/S V164-8.0MW/8.3MW | R86: =_xlfn.IFERROR(INDEX('model_byCAP'!$D$2:$D$377,MATCH(Q86,'model_byCAP'!$A$2:$A$377,0)),0) -> MHI.Vestas.V164.8400
A87: 570715000001613578 | B87: 43457 | C87: 8300 | D87: 164 | E87: 105 | F87: MHI Vestas Offshore Wind A/S | G87: V164-8.0MW/8.3MW | H87: 561 | I87: Esbjerg | J87: HAV | K87: Horns Rev | L87: Hav | M87: 412347 | N87: 6177795 | O87: Stamdata | P87: WH3 C01 | Q87: MHI Vestas Offshore Wind A/S V164-8.0MW/8.3MW | R87: =_xlfn.IFERROR(INDEX('model_byCAP'!$D$2:$D$377,MATCH(Q87,'model_byCAP'!$A$2:$A$377,0)),0) -> MHI.Vestas.V164.8400
A88: 570715000001613585 | B88: 43457 | C88: 8300 | D88: 164 | E88: 105 | F88: MHI Vestas Offshore Wind A/S | G88: V164-8.0MW/8.3MW | H88: 561 | I88: Esbjerg | J88: HAV | K88: Horns Rev | L88: Hav | M88: 412152 | N88: 6176707 | O88: Stamdata | P88: WH3 C02 | Q88: MHI Vestas Offshore Wind A/S V164-8.0MW/8.3MW | R88: =_xlfn.IFERROR(INDEX('model_byCAP'!$D$2:$D$377,MATCH(Q88,'model_byCAP'!$A$2:$A$377,0)),0) -> MHI.Vestas.V164.8400
A89: 570715000001613592 | B89: 43457 | C89: 8300 | D89: 164 | E89: 105 | F89: MHI Vestas Offshore Wind A/S | G89: V164-8.0MW/8.3MW | H89: 561 | I89: Esbjerg | J89: HAV | K89: Horns Rev | L89: Hav | M89: 412028 | N89: 6175608 | O89: Stamdata | P89: WH3 C03 | Q89: MHI Vestas Offshore Wind A/S V164-8.0MW/8.3MW | R89: =_xlfn.IFERROR(INDEX('model_byCAP'!$D$2:$D$377,MATCH(Q89,'model_byCAP'!$A$2:$A$377,0)),0) -> MHI.Vestas.V164.8400
A90: 570715000001613608 | B90: 43457 | C90: 8300 | D90: 164 | E90: 105 | F90: MHI Vestas Offshore Wind A/S | G90: V164-8.0MW/8.3MW | H90: 561 | I90: Esbjerg | J90: HAV | K90: Horns Rev | L90: Hav | M90: 411974 | N90: 6174504 | O90: Stamdata | P90: WH3 C04 | Q90: MHI Vestas Offshore Wind A/S V164-8.0MW/8.3MW | R90: =_xlfn.IFERROR(INDEX('model_byCAP'!$D$2:$D$377,MATCH(Q90,'model_byCAP'!$A$2:$A$377,0)),0) -> MHI.Vestas.V164.8400
A91: 570715000001613615 | B91: 43457 | C91: 8300 | D91: 164 | E91: 105 | F91: MHI Vestas Offshore Wind A/S | G91: V164-8.0MW/8.3MW | H91: 561 | I91: Esbjerg | J91: HAV | K91: Horns Rev | L91: Hav | M91: 411990 | N91: 6173399 | O91: Stamdata | P91: WH3 C05 | Q91: MHI Vestas Offshore Wind A/S V164-8.0MW/8.3MW | R91: =_xlfn.IFERROR(INDEX('model_byCAP'!$D$2:$D$377,MATCH(Q91,'model_byCAP'!$A$2:$A$377,0)),0) -> MHI.Vestas.V164.8400
... A128: 570715000001613981 | B128: 43457 | C128: 8300 | D128: 164 | E128: 105 | F128: MHI Vestas Offshore Wind A/S | G128: V164-8.0MW/8.3MW | H128: 561 | I128: Esbjerg | J128: HAV | K128: Horns Rev | L128: Hav | M128: 422847 | N128: 6171427 | O128: Stamdata | P128: WH3 J01 | Q128: MHI Vestas Offshore Wind A/S V164-8.0MW/8.3MW | R128: =_xlfn.IFERROR(INDEX('model_byCAP'!$D$2:$D$377,MATCH(Q128,'model_byCAP'!$A$2:$A$377,0)),0) -> MHI.Vestas.V164.8400
A129: 571313134402411891 | B129: 42372 | C129: 8000 | D129: 164 | E129: 118 | F129: Vestas Wind Systems A/S | G129: V164-8MW | H129: 561 | I129: Esbjerg | J129: LAND | K129: Esbjerg Jorde | L129: 5k | M129: 469033 | N129: 6145290 | O129: SDFE2018 | P129: 344241189 | Q129: Vestas Wind Systems A/S V164-8MW | R129: =_xlfn.IFERROR(INDEX('model_byCAP'!$D$2:$D$377,MATCH(Q129,'model_byCAP'!$A$2:$A$377,0)),0) -> Vestas.V164.8000
A130: 571313134402411907 | B130: 42356 | C130: 8000 | D130: 164 | E130: 118 | F130: Vestas Wind Systems A/S | G130: V164-8MW | H130: 561 | I130: Esbjerg | J130: LAND | K130: Esbjerg Jorde | L130: 5k | M130: 469542 | N130: 6145189 | O130: SDFE2018 | P130: 344241190 | Q130: Vestas Wind Systems A/S V164-8MW | R130: =_xlfn.IFERROR(INDEX('model_byCAP'!$D$2:$D$377,MATCH(Q130,'model_byCAP'!$A$2:$A$377,0)),0) -> Vestas.V164.8000
A131: 570715000001554987 | B131: 42783 | C131: 8000 | D131: 154 | E131: 120.5 | F131: Siemens Wind Power A/S | G131: SWT 8.0-154 | H131: 787 | I131: Thisted | J131: LAND | K131: Østrild by, Østerild | L131: 4m | M131: 492965.55 | N131: 6323732.3 | O131: SDFE2018 | P131: 3492005 | Q131: Siemens Wind Power A/S SWT 8.0-154 | R131: =_xlfn.IFERROR(INDEX('model_byCAP'!$D$2:$D$377,MATCH(Q131,'model_byCAP'!$A$2:$A$377,0)),0) -> Siemens.SWT.8.0.154
A132: 571313134701404280 | B132: 43148 | C132: 7000 | D132: 154 | E132: 85.3 | F132: Siemens Wind Power A/S | G132: SWT-7.0-154 | H132: 665 | I132: Lemvig | J132: HAV | K132: 99999x | L132: 99999x | M132: 453510 | N132: 6280335 | O132: Stamdata | Q132: Siemens Wind Power A/S SWT-7.0-154 | R132: =_xlfn.IFERROR(INDEX('model_byCAP'!$D$2:$D$377,MATCH(Q132,'model_byCAP'!$A$2:$A$377,0)),0) -> Siemens.Gamesa.SG.7.0.154
A133: 571313134702404289 | B133: 43148 | C133: 7000 | D133: 154 | E133: 85.3 | F133: Siemens Wind Power A/S | G133: SWT-7.0-154 | H133: 665 | I133: Lemvig | J133: HAV | K133: 99999X | L133: 99999X | M133: 453064 | N133: 6281196 | O133: Stamdata | Q133: Siemens Wind Power A/S SWT-7.0-154 | R133: =_xlfn.IFERROR(INDEX('model_byCAP'!$D$2:$D$377,MATCH(Q133,'model_byCAP'!$A$2:$A$377,0)),0) -> Siemens.Gamesa.SG.7.0.154
A134: 571313134703404288 | B134: 43148 | C134: 7000 | D134: 154 | E134: 85.3 | F134: Siemens Wind Power A/S | G134: SWT-7.0-154 | H134: 665 | I134: Lemvig | J134: HAV | K134: 99999X | L134: 99999X | M134: 454407 | N134: 6280817 | O134: Stamdata | Q134: Siemens Wind Power A/S SWT-7.0-154 | R134: =_xlfn.IFERROR(INDEX('model_byCAP'!$D$2:$D$377,MATCH(Q134,'model_byCAP'!$A$2:$A$377,0)),0) -> Siemens.Gamesa.SG.7.0.154
A135: 571313134704404287 | B135: 43148 | C135: 7000 | D135: 154 | E135: 85.3 | F135: Siemens Wind Power A/S | G135: SWT-7.0-154 | H135: 665 | I135: Lemvig | J135: HAV | K135: 99999X | L135: 99999X | M135: 454153 | N135: 6281691 | O135: Stamdata | Q135: Siemens Wind Power A/S SWT-7.0-154 | R135: =_xlfn.IFERROR(INDEX('model_byCAP'!$D$2:$D$377,MATCH(Q135,'model_byCAP'!$A$2:$A$377,0)),0) -> Siemens.Gamesa.SG.7.0.154
...

Sheet model_byCAP
A1: Turbine | B1: IC | C1: perc(%) | D1: column | E1: notes
A2: Siemens Wind Power A/S SG 8.0-167 DD | B2: 611400 | C2: 8.6905048 | D2: Siemens.Gamesa.SG.8.0.167
A3: SIEMENS SWT 2.3-93 | B3: 609500 | C3: 8.663498 | D3: Siemens.SWT.2.3.93
A4: MHI Vestas Offshore Wind A/S V164-8.0MW/8.3MW | B4: 433000 | C4: 6.1547082 | D4: MHI.Vestas.V164.8400
A5: SIEMENS SWT 3.6-120 | B5: 421200 | C5: 5.9869817 | D5: Siemens.SWT.3.6.120
A6: Ukendt Ukendt | B6: 240944.5 | C6: 3.4248108
A7: Vestas Wind Systems A/S V117-3.6 MW | B7: 234000 | C7: 3.326101 | D7: Vestas.V117.4000 | E7: approx.
A8: Vestas Wind Systems A/S V126-3.6 MW | B8: 234000 | C8: 3.326101 | D8: Vestas.V136.4000 | E8: approx.
A9: Vestas Wind Systems A/S V 47-660 | B9: 211800 | C9: 3.0105478 | D9: Vestas.V47.660
A10: NEG Micon NM 48/750 | B10: 208350 | C10: 2.9615091 | D10: NEG.Micon.NM48.750 | E10: approx.
A11: BONUS 2,3 MW | B11: 202400 | C11: 2.8769352 | D11: Bonus.B82.2300
A12: Vestas Wind Systems A/S V 90-3 MW | B12: 183000 | C12: 2.6011815 | D12: Vestas.V90.3000
A13: Vestas Wind Systems A/S V112-3.0MW | B13: 178725 | C13: 2.5404162 | D13: Vestas.V112.3000
A14: Vestas Wind Systems A/S V112-3.3MW | B14: 170550 | C14: 2.4242159 | D14: Vestas.V112.3300
A15: Vestas Wind Systems A/S V 80 | B15: 164000 | C15: 2.3311135 | D15: Vestas.V80.2000
A16: SIEMENS SWT 3.0-101 | B16: 162200 | C16: 2.3055281 | D16: Siemens.SWT.3.0.101
A17: SIEMENS SWT-3.2-113 DD | B17: 145600 | C17: 2.0695739 | D17: Siemens.SWT.3.0.101 | E17: approx.
A18: Vestas Wind Systems A/S V117-3.45 MW | B18: 134550 | C18: 1.9125081 | D18: Vestas.V117.4000 | E18: approx.
A19: Vestas Wind Systems A/S V 44-600 | B19: 129720 | C19: 1.8438539 | D19: Vestas.V44.600
A20: NEG Micon NM 750-200/48 | B20: 110250 | C20: 1.5671053 | D20: NEG.Micon.NM48.750
A21: BONUS 1 MW | B21: 108000 | C21: 1.5351235 | D21: Bonus.B54.1000 | E21: approx.
A22: NEG Micon NM 52/900 | B22: 89100 | C22: 1.2664769 | D22: NEG.Micon.NM52.900 | E22: approx.
A23: SIEMENS SWT-DD-130 Mode 1 | B23: 77400 | C23: 1.1001719 | D23: Siemens.SWT.4.3.130
A24: Vestas Wind Systems A/S V 52-850 | B24: 68000 | C24: 0.96655925 | D24: Vestas.V52.850
A25: Vestas Wind Systems A/S V126-3.45 | B25: 57000 | C25: 0.81020408 | D25: Vestas.V136.4000 | E25: approx.
A26: Nordex N 60/1300 | B26: 54600 | C26: 0.77609022 | D26: Nordex.N60.1300
A27: BONUS 2 MW | B27: 54000 | C27: 0.76756176 | D27: Bonus.B82.2300 | E27: approx.
A28: Vestas Wind Systems A/S V100-2.0 | B28: 52200 | C28: 0.74197637 | D28: Vestas.V100.2000
A29: Vestas Wind Systems A/S V 90 3 | B29: 51000 | C29: 0.72491944 | D29: Vestas.V90.3000
A30: Vestas Wind Systems A/S V 80 2 | B30: 46000 | C30: 0.65384891 | D30: Vestas.V80.2000
A31: NEG Micon NM 1500-750/175 | B31: 45000 | C31: 0.6396348 | D31: NEG.Micon.M1500.750 | E31: approx.
A32: Siemens Wind Power A/S SWT-3.2-101 DD | B32: 41600 | C32: 0.59130684 | D32: Siemens.SWT.3.0.101 | E32: approx.
A33: Vestas Wind Systems A/S V 47 | B33: 40950 | C33: 0.58206767 | D33: Vestas.V47.660
A34: Nordex N 50/800 | B34: 40000 | C34: 0.56856427 | D34: Nordex.N50.800
A35: Vestas Wind Systems A/S V 80-2 MW | B35: 40000 | C35: 0.56856427 | D35: Vestas.V80.2000
A36: Vestas Wind Systems A/S V 90 2 | B36: 40000 | C36: 0.56856427 | D36: Vestas.V90.2000
A37: Vestas Wind Systems A/S V 66 1,75 | B37: 38500 | C37: 0.54724311 | D37: Vestas.V66.1750
A38: Vestas Wind Systems A/S V136-4.2 MW | B38: 37800 | C38: 0.53729323 | D38: Vestas.V136.4000
A39: NEG Micon NM 64/1500 | B39: 36000 | C39: 0.51170784 | D39: NEG.Micon.NM64c.1500
A40: Siemens Wind Power A/S SWT-6.0-120 | B40: 36000 | C40: 0.51170784 | D40: Siemens.Gamesa.SG.6.0.154 | E40: approx.
...
